<?xml version="1.0" encoding="UTF-8" standalone="no"?>
<?pydev-testrun version="1.0"?><pydev-testsuite>
<summary errors="1" failures="0" finished="true" name="Test Run: 48" tests="0" total_time="Finished in: 0.00 secs."/>
<test location="C:/Users/Automation/Documents/MatchMe/Automation/MatchMe/tests/Test_Case1.py" status="error" test="Test_Case1" time="0">
<stdout/>
<stderr><![CDATA[Traceback (most recent call last):
  File "C:\Users\Automation\.p2\pool\plugins\org.python.pydev.core_6.3.2.201803171248\pysrc\_pydev_runfiles\pydev_runfiles.py", line 468, in __get_module_from_str
    mod = __import__(modname)
  File "C:\Users\Automation\Documents\MatchMe\Automation\MatchMe\tests\Test_Case1.py", line 6, in <module>
    from generics.BaseTest import BaseTest
  File "C:\Users\Automation\Documents\MatchMe\Automation\MatchMe\generics\BaseTest.py", line 14, in <module>
    from tests.Test_Case1 import Test_Case1
  File "C:\Users\Automation\Documents\MatchMe\Automation\MatchMe\tests\Test_Case1.py", line 6, in <module>
    from generics.BaseTest import BaseTest
ImportError: cannot import name BaseTest
ERROR: Module: Test_Case1 could not be imported (file: C:/Users/Automation/Documents/MatchMe/Automation/MatchMe/tests/Test_Case1.py).
]]></stderr>
</test>
<launch mode="run">
<launch_memento><![CDATA[<?xml version="1.0" encoding="UTF-8" standalone="no"?>
<launchConfiguration local="true" path="MatchMe tests"/>
]]></launch_memento>
</launch>
</pydev-testsuite>
