<?xml version="1.0" encoding="UTF-8" standalone="no"?>
<?pydev-testrun version="1.0"?><pydev-testsuite>
<summary errors="1" failures="0" finished="true" name="Test Run: 20" tests="1" total_time="Finished in: 4.19 secs."/>
<test location="C:\Users\Automation\Documents\MatchMe\Automation\MatchMe\generics\BaseTest.py" status="error" test="generics.BaseTest.BaseTest &lt;setUpClass&gt;" time="">
<stdout/>
<stderr><![CDATA[Traceback (most recent call last):
  File "C:\Users\Automation\Documents\MatchMe\Automation\MatchMe\generics\BaseTest.py", line 42, in setUpClass
    self.driver = webdriver.Remote('http://localhost:4723/wd/hub', self.desired_caps)
  File "C:\Python27\lib\site-packages\appium\webdriver\webdriver.py", line 36, in __init__
    super(WebDriver, self).__init__(command_executor, desired_capabilities, browser_profile, proxy, keep_alive)
  File "C:\Python27\lib\site-packages\selenium\webdriver\remote\webdriver.py", line 154, in __init__
    self.start_session(desired_capabilities, browser_profile)
  File "C:\Python27\lib\site-packages\selenium\webdriver\remote\webdriver.py", line 243, in start_session
    response = self.execute(Command.NEW_SESSION, parameters)
  File "C:\Python27\lib\site-packages\selenium\webdriver\remote\webdriver.py", line 310, in execute
    response = self.command_executor.execute(driver_command, params)
  File "C:\Python27\lib\site-packages\selenium\webdriver\remote\remote_connection.py", line 466, in execute
    return self._request(command_info[0], url, body=data)
  File "C:\Python27\lib\site-packages\selenium\webdriver\remote\remote_connection.py", line 528, in _request
    resp = opener.open(request, timeout=self._timeout)
  File "C:\Python27\lib\urllib2.py", line 429, in open
    response = self._open(req, data)
  File "C:\Python27\lib\urllib2.py", line 447, in _open
    '_open', req)
  File "C:\Python27\lib\urllib2.py", line 407, in _call_chain
    result = func(*args)
  File "C:\Python27\lib\urllib2.py", line 1228, in http_open
    return self.do_open(httplib.HTTPConnection, req)
  File "C:\Python27\lib\urllib2.py", line 1198, in do_open
    raise URLError(err)
URLError: <urlopen error [Errno 10061] No connection could be made because the target machine actively refused it>
]]></stderr>
</test>
<launch mode="run">
<launch_memento><![CDATA[<?xml version="1.0" encoding="UTF-8" standalone="no"?>
<launchConfiguration local="true" path="MatchMe BaseTest.py"/>
]]></launch_memento>
</launch>
</pydev-testsuite>
