<?xml version="1.0" encoding="UTF-8" standalone="no"?>
<?pydev-testrun version="1.0"?><pydev-testsuite>
<summary errors="1" failures="0" finished="true" name="Test Run: 46" tests="1" total_time="Finished in: 0.00 secs."/>
<test location="C:\Users\Automation\Documents\MatchMe\Automation\MatchMe\generics\BaseTest.py" status="error" test="tests.Test_Case1.Test_Case1 &lt;setUpClass&gt;" time="">
<stdout/>
<stderr><![CDATA[Traceback (most recent call last):
  File "C:\Users\Automation\Documents\MatchMe\Automation\MatchMe\generics\BaseTest.py", line 35, in setUpClass
    self.testRunner.run('test')
  File "C:\Python27\lib\site-packages\pyunitreport\runner.py", line 52, in run
    test(result)
TypeError: 'str' object is not callable
]]></stderr>
</test>
<launch mode="run">
<launch_memento><![CDATA[<?xml version="1.0" encoding="UTF-8" standalone="no"?>
<launchConfiguration local="true" path="MatchMe tests"/>
]]></launch_memento>
</launch>
</pydev-testsuite>
